Traceback (most recent call last):
  File "/usr/lib/python3/dist-packages/gpiozero/pins/pi.py", line 411, in pin
    pin = self.pins[info]
          ~~~~~~~~~^^^^^^
KeyError: PinInfo(number=7, name='GPIO4', names=frozenset({'GPIO4', 4, 'J8:7', 'BCM4', 'BOARD7', 'WPI7', '4'}), pull='', row=4, col=1, interfaces=frozenset({'', 'uart', 'dpi', 'spi', 'i2c', 'gpio'}))

During handling of the above exception, another exception occurred:

Traceback (most recent call last):
  File "/home/rednexhex/ctrl/pccctrl.py", line 15, in <module>
    sense1 = Button(sensepin1, pull_up=True)
             ^^^^^^^^^^^^^^^^^^^^^^^^^^^^^^^
  File "/usr/lib/python3/dist-packages/gpiozero/devices.py", line 108, in __call__
    self = super().__call__(*args, **kwargs)
           ^^^^^^^^^^^^^^^^^^^^^^^^^^^^^^^^^
  File "/usr/lib/python3/dist-packages/gpiozero/input_devices.py", line 412, in __init__
    super().__init__(
  File "/usr/lib/python3/dist-packages/gpiozero/mixins.py", line 417, in __init__
    super().__init__(*args, **kwargs)
  File "/usr/lib/python3/dist-packages/gpiozero/input_devices.py", line 162, in __init__
    super().__init__(
  File "/usr/lib/python3/dist-packages/gpiozero/mixins.py", line 243, in __init__
    super().__init__(*args, **kwargs)
  File "/usr/lib/python3/dist-packages/gpiozero/input_devices.py", line 79, in __init__
    super().__init__(pin, pin_factory=pin_factory)
  File "/usr/lib/python3/dist-packages/gpiozero/devices.py", line 553, in __init__
    pin = self.pin_factory.pin(pin)
          ^^^^^^^^^^^^^^^^^^^^^^^^^
  File "/usr/lib/python3/dist-packages/gpiozero/pins/pi.py", line 413, in pin
    pin = self.pin_class(self, info)
          ^^^^^^^^^^^^^^^^^^^^^^^^^^
  File "/usr/lib/python3/dist-packages/gpiozero/pins/lgpio.py", line 126, in __init__
    lgpio.gpio_claim_input(
  File "/usr/lib/python3/dist-packages/lgpio.py", line 755, in gpio_claim_input
    return _u2i(_lgpio._gpio_claim_input(handle&0xffff, lFlags, gpio))
           ^^^^^^^^^^^^^^^^^^^^^^^^^^^^^^^^^^^^^^^^^^^^^^^^^^^^^^^^^^^
  File "/usr/lib/python3/dist-packages/lgpio.py", line 458, in _u2i
    raise error(error_text(v))
lgpio.error: 'GPIO busy'
